Workbook

Sheet 00_maestro_productos
A1: id_producto | B1: producto | C1: categoria | D1: coste_objetivo | E1: precio_venta_recomendado | F1: margen_objetivo_pct
A2: P001 | B2: Auriculares inalámbricos | C2: Electrónica | D2: 84.31 | E2: 122.19 | F2: 0.31
A3: P002 | B3: Smartwatch | C3: Electrónica | D3: 47.23 | E3: 73.8 | F3: 0.36
A4: P003 | B4: Tablet 10" | C4: Electrónica | D4: 94.19 | E4: 177.72 | F4: 0.47
A5: P004 | B5: Altavoz Bluetooth | C5: Electrónica | D5: 110.03 | E5: 161.81 | F5: 0.32
A6: P005 | B6: Robot de cocina | C6: Hogar | D6: 41.17 | E6: 59.67 | F6: 0.31
A7: P006 | B7: Set de sartenes | C7: Hogar | D7: 26.63 | E7: 46.72 | F7: 0.43
A8: P007 | B8: Aspiradora sin cable | C8: Hogar | D8: 12.9 | E8: 19.85 | F8: 0.35
A9: P008 | B9: Lámpara LED de pie | C9: Hogar | D9: 57.47 | E9: 102.62 | F9: 0.44
A10: P009 | B10: Aceite de oliva virgen extra 1L | C10: Alimentación | D10: 4.32 | E10: 7.85 | F10: 0.45
A11: P010 | B11: Cava brut nature | C11: Alimentación | D11: 11.44 | E11: 16.34 | F11: 0.3
A12: P011 | B12: Café en grano 1kg | C12: Alimentación | D12: 11.4 | E12: 21.51 | F12: 0.47
A13: P012 | B13: Chocolate a la taza 500g | C13: Alimentación | D13: 5.77 | E13: 8.74 | F13: 0.34
... A21: P020 | B21: Set de maquillaje | C21: Perfumería y Belleza | D21: 33.78 | E21: 60.32 | F21: 0.44

Sheet 01_datos_crudos
A1: id_venta | B1: fecha | C1: año | D1: mes | E1: nombre_mes | F1: trimestre | G1: id_producto | H1: producto | I1: gama | J1: categoria | K1: cantidad | L1: precio_unitario | M1: coste_unitario | N1: descuento_pct | O1: ingresos | P1: costes | Q1: beneficio | R1: beneficio_pct | S1: comunidad_autonoma | T1: canal
A2: V00557 | B2: 45785 | C2: =YEAR(Tabla2[[#This Row],[fecha]]) -> 2025 | D2: =MONTH(Tabla2[[#This Row],[fecha]]) -> 5 | E2: =TEXT(Tabla2[[#This Row],[fecha]], "mmmm") -> mayo | F2: =F3 -> T3 | G2: P006 | H2: Set de sartenes | I2: =IF(Tabla2[[#This Row],[precio_unitario]]<=30,"Económico",IF(Tabla2[[#This Row],[precio_unitario]]<=58.49,"Accesible","Caro")) -> Accesible | J2: Hogar | K2: 7 | L2: 48.85 | M2: 26.46 | N2: 0 | O2: =K2*L2*(1-N2) -> 341.95 | P2: =M2*K2 -> 185.22 | Q2: =O2-P2 -> 156.73 | R2: =IFERROR(Q2/O2,0) -> 0.45834186 | S2: C. Valenciana | T2: online
A3: V01049 | B3: 45540 | C3: =YEAR(Tabla2[[#This Row],[fecha]]) -> 2024 | D3: =MONTH(Tabla2[[#This Row],[fecha]]) -> 9 | E3: =TEXT(Tabla2[[#This Row],[fecha]], "mmmm") -> septiembre | F3: ="T"&ROUNDUP(Tabla2[[#This Row],[mes]]/3,0) -> T3 | G3: P010 | H3: Cava brut nature | I3: =IF(Tabla2[[#This Row],[precio_unitario]]<=30,"Económico",IF(Tabla2[[#This Row],[precio_unitario]]<=58.49,"Accesible","Caro")) -> Económico | J3: Alimentación | K3: 4 | L3: 17.33 | M3: 10.93 | N3: 0 | O3: =K3*L3*(1-N3) -> 69.32 | P3: =M3*K3 -> 43.72 | Q3: =O3-P3 -> 25.6 | R3: =IFERROR(Q3/O3,0) -> 0.36930179 | S3: Sin dato | T3: online
A4: V00142 | B4: 45764 | C4: =YEAR(Tabla2[[#This Row],[fecha]]) -> 2025 | D4: =MONTH(Tabla2[[#This Row],[fecha]]) -> 4 | E4: =TEXT(Tabla2[[#This Row],[fecha]], "mmmm") -> abril | F4: ="T"&ROUNDUP(Tabla2[[#This Row],[mes]]/3,0) -> T2 | G4: P015 | H4: Zapatillas running | I4: =IF(Tabla2[[#This Row],[precio_unitario]]<=30,"Económico",IF(Tabla2[[#This Row],[precio_unitario]]<=58.49,"Accesible","Caro")) -> Caro | J4: Moda | K4: 3 | L4: 73.59 | M4: 41.51 | N4: 0 | O4: =K4*L4*(1-N4) -> 220.77 | P4: =M4*K4 -> 124.53 | Q4: =O4-P4 -> 96.24 | R4: =IFERROR(Q4/O4,0) -> 0.43592879 | S4: Baleares | T4: tienda_fisica
A5: V00916 | B5: 45428 | C5: =YEAR(Tabla2[[#This Row],[fecha]]) -> 2024 | D5: =MONTH(Tabla2[[#This Row],[fecha]]) -> 5 | E5: =TEXT(Tabla2[[#This Row],[fecha]], "mmmm") -> mayo | F5: ="T"&ROUNDUP(Tabla2[[#This Row],[mes]]/3,0) -> T2 | G5: P002 | H5: Smartwatch | I5: =IF(Tabla2[[#This Row],[precio_unitario]]<=30,"Económico",IF(Tabla2[[#This Row],[precio_unitario]]<=58.49,"Accesible","Caro")) -> Caro | J5: Electrónica | K5: 1 | L5: 75.75 | M5: 46.12 | N5: 0 | O5: =K5*L5*(1-N5) -> 75.75 | P5: =M5*K5 -> 46.12 | Q5: =O5-P5 -> 29.63 | R5: =IFERROR(Q5/O5,0) -> 0.39115512 | S5: C. Valenciana | T5: tienda_fisica
A6: V00003 | B6: 45993 | C6: =YEAR(Tabla2[[#This Row],[fecha]]) -> 2025 | D6: =MONTH(Tabla2[[#This Row],[fecha]]) -> 12 | E6: =TEXT(Tabla2[[#This Row],[fecha]], "mmmm") -> diciembre | F6: ="T"&ROUNDUP(Tabla2[[#This Row],[mes]]/3,0) -> T4 | G6: P008 | H6: Lámpara LED de pie | I6: =IF(Tabla2[[#This Row],[precio_unitario]]<=30,"Económico",IF(Tabla2[[#This Row],[precio_unitario]]<=58.49,"Accesible","Caro")) -> Caro | J6: Hogar | K6: 1 | L6: 107.63 | M6: 56.9 | N6: 0.28 | O6: =K6*L6*(1-N6) -> 77.4936 | P6: =M6*K6 -> 56.9 | Q6: =O6-P6 -> 20.5936 | R6: =IFERROR(Q6/O6,0) -> 0.26574582 | S6: Cataluña | T6: tienda_fisica
A7: V00579 | B7: 45531 | C7: =YEAR(Tabla2[[#This Row],[fecha]]) -> 2024 | D7: =MONTH(Tabla2[[#This Row],[fecha]]) -> 8 | E7: =TEXT(Tabla2[[#This Row],[fecha]], "mmmm") -> agosto | F7: ="T"&ROUNDUP(Tabla2[[#This Row],[mes]]/3,0) -> T3 | G7: P018 | H7: Crema facial hidratante | I7: =IF(Tabla2[[#This Row],[precio_unitario]]<=30,"Económico",IF(Tabla2[[#This Row],[precio_unitario]]<=58.49,"Accesible","Caro")) -> Accesible | J7: Perfumería y Belleza | K7: 3 | L7: 32.74 | M7: 16.47 | N7: 0 | O7: =K7*L7*(1-N7) -> 98.22 | P7: =M7*K7 -> 49.41 | Q7: =O7-P7 -> 48.81 | R7: =IFERROR(Q7/O7,0) -> 0.49694563 | S7: Cataluña | T7: tienda_fisica
A8: V00712 | B8: 45695 | C8: =YEAR(Tabla2[[#This Row],[fecha]]) -> 2025 | D8: =MONTH(Tabla2[[#This Row],[fecha]]) -> 2 | E8: =TEXT(Tabla2[[#This Row],[fecha]], "mmmm") -> febrero | F8: ="T"&ROUNDUP(Tabla2[[#This Row],[mes]]/3,0) -> T1 | G8: P004 | H8: Altavoz Bluetooth | I8: =IF(Tabla2[[#This Row],[precio_unitario]]<=30,"Económico",IF(Tabla2[[#This Row],[precio_unitario]]<=58.49,"Accesible","Caro")) -> Caro | J8: Electrónica | K8: 1 | L8: 149.61 | M8: =INDEX(Tabla3[coste_objetivo], MATCH(Tabla2[[#This Row],[id_producto]], Tabla3[id_producto],0)) -> 110.03 | N8: 0 | O8: =K8*L8*(1-N8) -> 149.61 | P8: =M8*K8 -> 110.03 | Q8: =O8-P8 -> 39.58 | R8: =IFERROR(Q8/O8,0) -> 0.26455451 | S8: Cataluña | T8: tienda_fisica
A9: V00152 | B9: 45760 | C9: =YEAR(Tabla2[[#This Row],[fecha]]) -> 2025 | D9: =MONTH(Tabla2[[#This Row],[fecha]]) -> 4 | E9: =TEXT(Tabla2[[#This Row],[fecha]], "mmmm") -> abril | F9: ="T"&ROUNDUP(Tabla2[[#This Row],[mes]]/3,0) -> T2 | G9: P003 | H9: Tablet 10" | I9: =IF(Tabla2[[#This Row],[precio_unitario]]<=30,"Económico",IF(Tabla2[[#This Row],[precio_unitario]]<=58.49,"Accesible","Caro")) -> Caro | J9: Electrónica | K9: 6 | L9: 172.48 | M9: 92.4 | N9: 0 | O9: =K9*L9*(1-N9) -> 1034.88 | P9: =M9*K9 -> 554.4 | Q9: =O9-P9 -> 480.48 | R9: =IFERROR(Q9/O9,0) -> 0.46428571 | S9: Cataluña | T9: online
A10: V00268 | B10: 45793 | C10: =YEAR(Tabla2[[#This Row],[fecha]]) -> 2025 | D10: =MONTH(Tabla2[[#This Row],[fecha]]) -> 5 | E10: =TEXT(Tabla2[[#This Row],[fecha]], "mmmm") -> mayo | F10: ="T"&ROUNDUP(Tabla2[[#This Row],[mes]]/3,0) -> T2 | G10: P013 | H10: Camiseta básica algodón | I10: =IF(Tabla2[[#This Row],[precio_unitario]]<=30,"Económico",IF(Tabla2[[#This Row],[precio_unitario]]<=58.49,"Accesible","Caro")) -> Caro | J10: Moda | K10: 4 | L10: 71.59 | M10: 49.02 | N10: 0 | O10: =K10*L10*(1-N10) -> 286.36 | P10: =M10*K10 -> 196.08 | Q10: =O10-P10 -> 90.28 | R10: =IFERROR(Q10/O10,0) -> 0.3152675 | S10: Cataluña | T10: tienda_fisica
A11: V01897 | B11: 45755 | C11: =YEAR(Tabla2[[#This Row],[fecha]]) -> 2025 | D11: =MONTH(Tabla2[[#This Row],[fecha]]) -> 4 | E11: =TEXT(Tabla2[[#This Row],[fecha]], "mmmm") -> abril | F11: ="T"&ROUNDUP(Tabla2[[#This Row],[mes]]/3,0) -> T2 | G11: P015 | H11: Zapatillas running | I11: =IF(Tabla2[[#This Row],[precio_unitario]]<=30,"Económico",IF(Tabla2[[#This Row],[precio_unitario]]<=58.49,"Accesible","Caro")) -> Caro | J11: Moda | K11: 4 | L11: 74 | M11: 40.67 | N11: 0 | O11: =K11*L11*(1-N11) -> 296 | P11: =M11*K11 -> 162.68 | Q11: =O11-P11 -> 133.32 | R11: =IFERROR(Q11/O11,0) -> 0.45040541 | S11: Cataluña | T11: tienda_fisica
A12: V00263 | B12: 45851 | C12: =YEAR(Tabla2[[#This Row],[fecha]]) -> 2025 | D12: =MONTH(Tabla2[[#This Row],[fecha]]) -> 7 | E12: =TEXT(Tabla2[[#This Row],[fecha]], "mmmm") -> julio | F12: ="T"&ROUNDUP(Tabla2[[#This Row],[mes]]/3,0) -> T3 | G12: P015 | H12: Zapatillas running | I12: =IF(Tabla2[[#This Row],[precio_unitario]]<=30,"Económico",IF(Tabla2[[#This Row],[precio_unitario]]<=58.49,"Accesible","Caro")) -> Caro | J12: Moda | K12: 5 | L12: 74.66 | M12: 44.39 | N12: 0.12 | O12: =K12*L12*(1-N12) -> 328.504 | P12: =M12*K12 -> 221.95 | Q12: =O12-P12 -> 106.554 | R12: =IFERROR(Q12/O12,0) -> 0.32436135 | S12: Cataluña | T12: tienda_fisica
A13: V00880 | B13: 45314 | C13: =YEAR(Tabla2[[#This Row],[fecha]]) -> 2024 | D13: =MONTH(Tabla2[[#This Row],[fecha]]) -> 1 | E13: =TEXT(Tabla2[[#This Row],[fecha]], "mmmm") -> enero | F13: ="T"&ROUNDUP(Tabla2[[#This Row],[mes]]/3,0) -> T1 | G13: P006 | H13: Set de sartenes | I13: =IF(Tabla2[[#This Row],[precio_unitario]]<=30,"Económico",IF(Tabla2[[#This Row],[precio_unitario]]<=58.49,"Accesible","Caro")) -> Accesible | J13: Hogar | K13: 4 | L13: 48.65 | M13: 26.34 | N13: 0 | O13: =K13*L13*(1-N13) -> 194.6 | P13: =M13*K13 -> 105.36 | Q13: =O13-P13 -> 89.24 | R13: =IFERROR(Q13/O13,0) -> 0.45858171 | S13: C. Valenciana | T13: online
A14: V01030 | B14: 45359 | C14: =YEAR(Tabla2[[#This Row],[fecha]]) -> 2024 | D14: =MONTH(Tabla2[[#This Row],[fecha]]) -> 3 | E14: =TEXT(Tabla2[[#This Row],[fecha]], "mmmm") -> marzo | F14: ="T"&ROUNDUP(Tabla2[[#This Row],[mes]]/3,0) -> T1 | G14: P008 | H14: Lámpara LED de pie | I14: =IF(Tabla2[[#This Row],[precio_unitario]]<=30,"Económico",IF(Tabla2[[#This Row],[precio_unitario]]<=58.49,"Accesible","Caro")) -> Caro | J14: Hogar | K14: 10 | L14: 101.05 | M14: 56.85 | N14: 0 | O14: =K14*L14*(1-N14) -> 1010.5 | P14: =M14*K14 -> 568.5 | Q14: =O14-P14 -> 442 | R14: =IFERROR(Q14/O14,0) -> 0.43740722 | S14: C. Valenciana | T14: online
A15: V01643 | B15: 45531 | C15: =YEAR(Tabla2[[#This Row],[fecha]]) -> 2024 | D15: =MONTH(Tabla2[[#This Row],[fecha]]) -> 8 | E15: =TEXT(Tabla2[[#This Row],[fecha]], "mmmm") -> agosto | F15: ="T"&ROUNDUP(Tabla2[[#This Row],[mes]]/3,0) -> T3 | G15: P015 | H15: Zapatillas running | I15: =IF(Tabla2[[#This Row],[precio_unitario]]<=30,"Económico",IF(Tabla2[[#This Row],[precio_unitario]]<=58.49,"Accesible","Caro")) -> Caro | J15: Moda | K15: 1 | L15: 74.6 | M15: 41.14 | N15: 0 | O15: =K15*L15*(1-N15) -> 74.6 | P15: =M15*K15 -> 41.14 | Q15: =O15-P15 -> 33.46 | R15: =IFERROR(Q15/O15,0) -> 0.44852547 | S15: Baleares | T15: tienda_fisica
A16: V01125 | B16: 45736 | C16: =YEAR(Tabla2[[#This Row],[fecha]]) -> 2025 | D16: =MONTH(Tabla2[[#This Row],[fecha]]) -> 3 | E16: =TEXT(Tabla2[[#This Row],[fecha]], "mmmm") -> marzo | F16: ="T"&ROUNDUP(Tabla2[[#This Row],[mes]]/3,0) -> T1 | G16: P001 | H16: Auriculares inalámbricos | I16: =IF(Tabla2[[#This Row],[precio_unitario]]<=30,"Económico",IF(Tabla2[[#This Row],[precio_unitario]]<=58.49,"Accesible","Caro")) -> Caro | J16: Electrónica | K16: 1 | L16: 120.59 | M16: 82.31 | N16: 0 | O16: =K16*L16*(1-N16) -> 120.59 | P16: =M16*K16 -> 82.31 | Q16: =O16-P16 -> 38.28 | R16: =IFERROR(Q16/O16,0) -> 0.31743926 | S16: Cataluña | T16: tienda_fisica
A17: V01862 | B17: 45534 | C17: =YEAR(Tabla2[[#This Row],[fecha]]) -> 2024 | D17: =MONTH(Tabla2[[#This Row],[fecha]]) -> 8 | E17: =TEXT(Tabla2[[#This Row],[fecha]], "mmmm") -> agosto | F17: ="T"&ROUNDUP(Tabla2[[#This Row],[mes]]/3,0) -> T3 | G17: P011 | H17: Café en grano 1kg | I17: =IF(Tabla2[[#This Row],[precio_unitario]]<=30,"Económico",IF(Tabla2[[#This Row],[precio_unitario]]<=58.49,"Accesible","Caro")) -> Económico | J17: Alimentación | K17: 5 | L17: 20.02 | M17: =INDEX(Tabla3[coste_objetivo], MATCH(Tabla2[[#This Row],[id_producto]], Tabla3[id_producto],0)) -> 11.4 | N17: 0 | O17: =K17*L17*(1-N17) -> 100.1 | P17: =M17*K17 -> 57 | Q17: =O17-P17 -> 43.1 | R17: =IFERROR(Q17/O17,0) -> 0.43056943 | S17: C. Valenciana | T17: tienda_fisica
A18: V00201 | B18: 45842 | C18: =YEAR(Tabla2[[#This Row],[fecha]]) -> 2025 | D18: =MONTH(Tabla2[[#This Row],[fecha]]) -> 7 | E18: =TEXT(Tabla2[[#This Row],[fecha]], "mmmm") -> julio | F18: ="T"&ROUNDUP(Tabla2[[#This Row],[mes]]/3,0) -> T3 | G18: P016 | H18: Bolso bandolera | I18: =IF(Tabla2[[#This Row],[precio_unitario]]<=30,"Económico",IF(Tabla2[[#This Row],[precio_unitario]]<=58.49,"Accesible","Caro")) -> Caro | J18: Moda | K18: 6 | L18: 80.08 | M18: 42.19 | N18: 0 | O18: =K18*L18*(1-N18) -> 480.48 | P18: =M18*K18 -> 253.14 | Q18: =O18-P18 -> 227.34 | R18: =IFERROR(Q18/O18,0) -> 0.47315185 | S18: Baleares | T18: tienda_fisica
A19: V02278 | B19: 45657 | C19: =YEAR(Tabla2[[#This Row],[fecha]]) -> 2024 | D19: =MONTH(Tabla2[[#This Row],[fecha]]) -> 12 | E19: =TEXT(Tabla2[[#This Row],[fecha]], "mmmm") -> diciembre | F19: ="T"&ROUNDUP(Tabla2[[#This Row],[mes]]/3,0) -> T4 | G19: P018 | H19: Crema facial hidratante | I19: =IF(Tabla2[[#This Row],[precio_unitario]]<=30,"Económico",IF(Tabla2[[#This Row],[precio_unitario]]<=58.49,"Accesible","Caro")) -> Económico | J19: Perfumería y Belleza | K19: 3 | L19: 29.76 | M19: 17.11 | N19: 0 | O19: =K19*L19*(1-N19) -> 89.28 | P19: =M19*K19 -> 51.33 | Q19: =O19-P19 -> 37.95 | R19: =IFERROR(Q19/O19,0) -> 0.4250672 | S19: Cataluña | T19: tienda_fisica
A20: V01650 | B20: 45990 | C20: =YEAR(Tabla2[[#This Row],[fecha]]) -> 2025 | D20: =MONTH(Tabla2[[#This Row],[fecha]]) -> 11 | E20: =TEXT(Tabla2[[#This Row],[fecha]], "mmmm") -> noviembre | F20: ="T"&ROUNDUP(Tabla2[[#This Row],[mes]]/3,0) -> T4 | G20: P018 | H20: Crema facial hidratante | I20: =IF(Tabla2[[#This Row],[precio_unitario]]<=30,"Económico",IF(Tabla2[[#This Row],[precio_unitario]]<=58.49,"Accesible","Caro")) -> Accesible | J20: Perfumería y Belleza | K20: 4 | L20: 31.14 | M20: 16.47 | N20: 0 | O20: =K20*L20*(1-N20) -> 124.56 | P20: =M20*K20 -> 65.88 | Q20: =O20-P20 -> 58.68 | R20: =IFERROR(Q20/O20,0) -> 0.47109827 | S20: Cataluña | T20: tienda_fisica
A21: V00833 | B21: 45345 | C21: =YEAR(Tabla2[[#This Row],[fecha]]) -> 2024 | D21: =MONTH(Tabla2[[#This Row],[fecha]]) -> 2 | E21: =TEXT(Tabla2[[#This Row],[fecha]], "mmmm") -> febrero | F21: ="T"&ROUNDUP(Tabla2[[#This Row],[mes]]/3,0) -> T1 | G21: P015 | H21: Zapatillas running | I21: =IF(Tabla2[[#This Row],[precio_unitario]]<=30,"Económico",IF(Tabla2[[#This Row],[precio_unitario]]<=58.49,"Accesible","Caro")) -> Caro | J21: Moda | K21: 2 | L21: 74.68 | M21: =INDEX(Tabla3[coste_objetivo], MATCH(Tabla2[[#This Row],[id_producto]], Tabla3[id_producto],0)) -> 42.79 | N21: 0.05 | O21: =K21*L21*(1-N21) -> 141.892 | P21: =M21*K21 -> 85.58 | Q21: =O21-P21 -> 56.312 | R21: =IFERROR(Q21/O21,0) -> 0.39686522 | S21: Madrid | T21: online
A22: V00849 | B22: 45681 | C22: =YEAR(Tabla2[[#This Row],[fecha]]) -> 2025 | D22: =MONTH(Tabla2[[#This Row],[fecha]]) -> 1 | E22: =TEXT(Tabla2[[#This Row],[fecha]], "mmmm") -> enero | F22: ="T"&ROUNDUP(Tabla2[[#This Row],[mes]]/3,0) -> T1 | G22: P009 | H22: Aceite de oliva virgen extra 1L | I22: =IF(Tabla2[[#This Row],[precio_unitario]]<=30,"Económico",IF(Tabla2[[#This Row],[precio_unitario]]<=58.49,"Accesible","Caro")) -> Económico | J22: Alimentación | K22: 2 | L22: 7.31 | M22: 4.16 | N22: 0 | O22: =K22*L22*(1-N22) -> 14.62 | P22: =M22*K22 -> 8.32 | Q22: =O22-P22 -> 6.3 | R22: =IFERROR(Q22/O22,0) -> 0.43091655 | S22: Sin dato | T22: tienda_fisica
A23: V00233 | B23: 45458 | C23: =YEAR(Tabla2[[#This Row],[fecha]]) -> 2024 | D23: =MONTH(Tabla2[[#This Row],[fecha]]) -> 6 | E23: =TEXT(Tabla2[[#This Row],[fecha]], "mmmm") -> junio | F23: ="T"&ROUNDUP(Tabla2[[#This Row],[mes]]/3,0) -> T2 | G23: P010 | H23: Cava brut nature | I23: =IF(Tabla2[[#This Row],[precio_unitario]]<=30,"Económico",IF(Tabla2[[#This Row],[precio_unitario]]<=58.49,"Accesible","Caro")) -> Económico | J23: Alimentación | K23: 8 | L23: 16.45 | M23: 11.31 | N23: 0 | O23: =K23*L23*(1-N23) -> 131.6 | P23: =M23*K23 -> 90.48 | Q23: =O23-P23 -> 41.12 | R23: =IFERROR(Q23/O23,0) -> 0.31246201 | S23: Madrid | T23: tienda_fisica
A24: V00401 | B24: 45709 | C24: =YEAR(Tabla2[[#This Row],[fecha]]) -> 2025 | D24: =MONTH(Tabla2[[#This Row],[fecha]]) -> 2 | E24: =TEXT(Tabla2[[#This Row],[fecha]], "mmmm") -> febrero | F24: ="T"&ROUNDUP(Tabla2[[#This Row],[mes]]/3,0) -> T1 | G24: P009 | H24: Aceite de oliva virgen extra 1L | I24: =IF(Tabla2[[#This Row],[precio_unitario]]<=30,"Económico",IF(Tabla2[[#This Row],[precio_unitario]]<=58.49,"Accesible","Caro")) -> Económico | J24: Alimentación | K24: 2 | L24: 8.07 | M24: 4.34 | N24: 0 | O24: =K24*L24*(1-N24) -> 16.14 | P24: =M24*K24 -> 8.68 | Q24: =O24-P24 -> 7.46 | R24: =IFERROR(Q24/O24,0) -> 0.4622057 | S24: C. Valenciana | T24: tienda_fisica
A25: V00864 | B25: 45973 | C25: =YEAR(Tabla2[[#This Row],[fecha]]) -> 2025 | D25: =MONTH(Tabla2[[#This Row],[fecha]]) -> 11 | E25: =TEXT(Tabla2[[#This Row],[fecha]], "mmmm") -> noviembre | F25: ="T"&ROUNDUP(Tabla2[[#This Row],[mes]]/3,0) -> T4 | G25: P012 | H25: Chocolate a la taza 500g | I25: =IF(Tabla2[[#This Row],[precio_unitario]]<=30,"Económico",IF(Tabla2[[#This Row],[precio_unitario]]<=58.49,"Accesible","Caro")) -> Económico | J25: Alimentación | K25: 8 | L25: 8.08 | M25: 5.55 | N25: 0 | O25: =K25*L25*(1-N25) -> 64.64 | P25: =M25*K25 -> 44.4 | Q25: =O25-P25 -> 20.24 | R25: =IFERROR(Q25/O25,0) -> 0.31311881 | S25: C. Valenciana | T25: tienda_fisica
A26: V01681 | B26: 45478 | C26: =YEAR(Tabla2[[#This Row],[fecha]]) -> 2024 | D26: =MONTH(Tabla2[[#This Row],[fecha]]) -> 7 | E26: =TEXT(Tabla2[[#This Row],[fecha]], "mmmm") -> julio | F26: ="T"&ROUNDUP(Tabla2[[#This Row],[mes]]/3,0) -> T3 | G26: P018 | H26: Crema facial hidratante | I26: =IF(Tabla2[[#This Row],[precio_unitario]]<=30,"Económico",IF(Tabla2[[#This Row],[precio_unitario]]<=58.49,"Accesible","Caro")) -> Accesible | J26: Perfumería y Belleza | K26: 1 | L26: 31.49 | M26: 17.11 | N26: 0 | O26: =K26*L26*(1-N26) -> 31.49 | P26: =M26*K26 -> 17.11 | Q26: =O26-P26 -> 14.38 | R26: =IFERROR(Q26/O26,0) -> 0.45665291 | S26: Madrid | T26: online
A27: V01924 | B27: 46007 | C27: =YEAR(Tabla2[[#This Row],[fecha]]) -> 2025 | D27: =MONTH(Tabla2[[#This Row],[fecha]]) -> 12 | E27: =TEXT(Tabla2[[#This Row],[fecha]], "mmmm") -> diciembre | F27: ="T"&ROUNDUP(Tabla2[[#This Row],[mes]]/3,0) -> T4 | G27: P019 | H27: Champú reparador | I27: =IF(Tabla2[[#This Row],[precio_unitario]]<=30,"Económico",IF(Tabla2[[#This Row],[precio_unitario]]<=58.49,"Accesible","Caro")) -> Accesible | J27: Perfumería y Belleza | K27: 4 | L27: 58.3 | M27: 32.06 | N27: 0.18 | O27: =K27*L27*(1-N27) -> 191.224 | P27: =M27*K27 -> 128.24 | Q27: =O27-P27 -> 62.984 | R27: =IFERROR(Q27/O27,0) -> 0.32937288 | S27: Madrid | T27: online
A28: V00652 | B28: 45496 | C28: =YEAR(Tabla2[[#This Row],[fecha]]) -> 2024 | D28: =MONTH(Tabla2[[#This Row],[fecha]]) -> 7 | E28: =TEXT(Tabla2[[#This Row],[fecha]], "mmmm") -> julio | F28: ="T"&ROUNDUP(Tabla2[[#This Row],[mes]]/3,0) -> T3 | G28: P019 | H28: Champú reparador | I28: =IF(Tabla2[[#This Row],[precio_unitario]]<=30,"Económico",IF(Tabla2[[#This Row],[precio_unitario]]<=58.49,"Accesible","Caro")) -> Caro | J28: Perfumería y Belleza | K28: 1 | L28: 63.62 | M28: 34.15 | N28: 0 | O28: =K28*L28*(1-N28) -> 63.62 | P28: =M28*K28 -> 34.15 | Q28: =O28-P28 -> 29.47 | R28: =IFERROR(Q28/O28,0) -> 0.46321911 | S28: Cataluña | T28: online
A29: V00035 | B29: 45664 | C29: =YEAR(Tabla2[[#This Row],[fecha]]) -> 2025 | D29: =MONTH(Tabla2[[#This Row],[fecha]]) -> 1 | E29: =TEXT(Tabla2[[#This Row],[fecha]], "mmmm") -> enero | F29: ="T"&ROUNDUP(Tabla2[[#This Row],[mes]]/3,0) -> T1 | G29: P007 | H29: Aspiradora sin cable | I29: =IF(Tabla2[[#This Row],[precio_unitario]]<=30,"Económico",IF(Tabla2[[#This Row],[precio_unitario]]<=58.49,"Accesible","Caro")) -> Económico | J29: Hogar | K29: 4 | L29: 21.12 | M29: 12.91 | N29: 0 | O29: =K29*L29*(1-N29) -> 84.48 | P29: =M29*K29 -> 51.64 | Q29: =O29-P29 -> 32.84 | R29: =IFERROR(Q29/O29,0) -> 0.38873106 | S29: C. Valenciana | T29: tienda_fisica
A30: V01396 | B30: 45857 | C30: =YEAR(Tabla2[[#This Row],[fecha]]) -> 2025 | D30: =MONTH(Tabla2[[#This Row],[fecha]]) -> 7 | E30: =TEXT(Tabla2[[#This Row],[fecha]], "mmmm") -> julio | F30: ="T"&ROUNDUP(Tabla2[[#This Row],[mes]]/3,0) -> T3 | G30: P011 | H30: Café en grano 1kg | I30: =IF(Tabla2[[#This Row],[precio_unitario]]<=30,"Económico",IF(Tabla2[[#This Row],[precio_unitario]]<=58.49,"Accesible","Caro")) -> Económico | J30: Alimentación | K30: 1 | L30: 20.9 | M30: 11.03 | N30: 0 | O30: =K30*L30*(1-N30) -> 20.9 | P30: =M30*K30 -> 11.03 | Q30: =O30-P30 -> 9.87 | R30: =IFERROR(Q30/O30,0) -> 0.4722488 | S30: C. Valenciana | T30: online
A31: V01023 | B31: 46003 | C31: =YEAR(Tabla2[[#This Row],[fecha]]) -> 2025 | D31: =MONTH(Tabla2[[#This Row],[fecha]]) -> 12 | E31: =TEXT(Tabla2[[#This Row],[fecha]], "mmmm") -> diciembre | F31: ="T"&ROUNDUP(Tabla2[[#This Row],[mes]]/3,0) -> T4 | G31: P007 | H31: Aspiradora sin cable | I31: =IF(Tabla2[[#This Row],[precio_unitario]]<=30,"Económico",IF(Tabla2[[#This Row],[precio_unitario]]<=58.49,"Accesible","Caro")) -> Económico | J31: Hogar | K31: 1 | L31: 18.86 | M31: 12.39 | N31: 0.2 | O31: =K31*L31*(1-N31) -> 15.088 | P31: =M31*K31 -> 12.39 | Q31: =O31-P31 -> 2.698 | R31: =IFERROR(Q31/O31,0) -> 0.1788176 | S31: Cataluña | T31: tienda_fisica
A32: V00197 | B32: 45729 | C32: =YEAR(Tabla2[[#This Row],[fecha]]) -> 2025 | D32: =MONTH(Tabla2[[#This Row],[fecha]]) -> 3 | E32: =TEXT(Tabla2[[#This Row],[fecha]], "mmmm") -> marzo | F32: ="T"&ROUNDUP(Tabla2[[#This Row],[mes]]/3,0) -> T1 | G32: P013 | H32: Camiseta básica algodón | I32: =IF(Tabla2[[#This Row],[precio_unitario]]<=30,"Económico",IF(Tabla2[[#This Row],[precio_unitario]]<=58.49,"Accesible","Caro")) -> Caro | J32: Moda | K32: 4 | L32: 72.39 | M32: 46.78 | N32: 0 | O32: =K32*L32*(1-N32) -> 289.56 | P32: =M32*K32 -> 187.12 | Q32: =O32-P32 -> 102.44 | R32: =IFERROR(Q32/O32,0) -> 0.35377815 | S32: C. Valenciana | T32: online
A33: V00413 | B33: 45848 | C33: =YEAR(Tabla2[[#This Row],[fecha]]) -> 2025 | D33: =MONTH(Tabla2[[#This Row],[fecha]]) -> 7 | E33: =TEXT(Tabla2[[#This Row],[fecha]], "mmmm") -> julio | F33: ="T"&ROUNDUP(Tabla2[[#This Row],[mes]]/3,0) -> T3 | G33: P009 | H33: Aceite de oliva virgen extra 1L | I33: =IF(Tabla2[[#This Row],[precio_unitario]]<=30,"Económico",IF(Tabla2[[#This Row],[precio_unitario]]<=58.49,"Accesible","Caro")) -> Económico | J33: Alimentación | K33: 4 | L33: 7.71 | M33: 4.49 | N33: 0 | O33: =K33*L33*(1-N33) -> 30.84 | P33: =M33*K33 -> 17.96 | Q33: =O33-P33 -> 12.88 | R33: =IFERROR(Q33/O33,0) -> 0.41763943 | S33: Aragón | T33: tienda_fisica
... A45: V00195 | B45: 45597 | C45: =YEAR(Tabla2[[#This Row],[fecha]]) -> 2024 | D45: =MONTH(Tabla2[[#This Row],[fecha]]) -> 11 | E45: =TEXT(Tabla2[[#This Row],[fecha]], "mmmm") -> noviembre | F45: ="T"&ROUNDUP(Tabla2[[#This Row],[mes]]/3,0) -> T4 | G45: P001 | H45: Auriculares inalámbricos | I45: =IF(Tabla2[[#This Row],[precio_unitario]]<=30,"Económico",IF(Tabla2[[#This Row],[precio_unitario]]<=58.49,"Accesible","Caro")) -> Caro | J45: Electrónica | K45: 3 | L45: 129.05 | M45: 84.04 | N45: 0.08 | O45: =K45*L45*(1-N45) -> 356.178 | P45: =M45*K45 -> 252.12 | Q45: =O45-P45 -> 104.058 | R45: =IFERROR(Q45/O45,0) -> 0.29215168 | S45: Madrid | T45: online
A46: V00906 | B46: 45461 | C46: =YEAR(Tabla2[[#This Row],[fecha]]) -> 2024 | D46: =MONTH(Tabla2[[#This Row],[fecha]]) -> 6 | E46: =TEXT(Tabla2[[#This Row],[fecha]], "mmmm") -> junio | F46: ="T"&ROUNDUP(Tabla2[[#This Row],[mes]]/3,0) -> T2 | G46: P003 | H46: Tablet 10" | I46: =IF(Tabla2[[#This Row],[precio_unitario]]<=30,"Económico",IF(Tabla2[[#This Row],[precio_unitario]]<=58.49,"Accesible","Caro")) -> Caro | J46: Electrónica | K46: 1 | L46: =INDEX(Tabla3[precio_venta_recomendado], MATCH(Tabla2[[#This Row],[id_producto]], Tabla3[id_producto], 0)) -> 177.72 | M46: 89.58 | N46: 0 | O46: =K46*L46*(1-N46) -> 177.72 | P46: =M46*K46 -> 89.58 | Q46: =O46-P46 -> 88.14 | R46: =IFERROR(Q46/O46,0) -> 0.49594868 | S46: Madrid | T46: online
A47: V00825 | B47: 45692 | C47: =YEAR(Tabla2[[#This Row],[fecha]]) -> 2025 | D47: =MONTH(Tabla2[[#This Row],[fecha]]) -> 2 | E47: =TEXT(Tabla2[[#This Row],[fecha]], "mmmm") -> febrero | F47: ="T"&ROUNDUP(Tabla2[[#This Row],[mes]]/3,0) -> T1 | G47: P010 | H47: Cava brut nature | I47: =IF(Tabla2[[#This Row],[precio_unitario]]<=30,"Económico",IF(Tabla2[[#This Row],[precio_unitario]]<=58.49,"Accesible","Caro")) -> Económico | J47: Alimentación | K47: 1 | L47: 17.39 | M47: 11.71 | N47: 0 | O47: =K47*L47*(1-N47) -> 17.39 | P47: =M47*K47 -> 11.71 | Q47: =O47-P47 -> 5.68 | R47: =IFERROR(Q47/O47,0) -> 0.3266245 | S47: Madrid | T47: tienda_fisica
A48: V01956 | B48: 45361 | C48: =YEAR(Tabla2[[#This Row],[fecha]]) -> 2024 | D48: =MONTH(Tabla2[[#This Row],[fecha]]) -> 3 | E48: =TEXT(Tabla2[[#This Row],[fecha]], "mmmm") -> marzo | F48: ="T"&ROUNDUP(Tabla2[[#This Row],[mes]]/3,0) -> T1 | G48: P015 | H48: Zapatillas running | I48: =IF(Tabla2[[#This Row],[precio_unitario]]<=30,"Económico",IF(Tabla2[[#This Row],[precio_unitario]]<=58.49,"Accesible","Caro")) -> Caro | J48: Moda | K48: 7 | L48: 82.99 | M48: 40.72 | N48: 0 | O48: =K48*L48*(1-N48) -> 580.93 | P48: =M48*K48 -> 285.04 | Q48: =O48-P48 -> 295.89 | R48: =IFERROR(Q48/O48,0) -> 0.50933847 | S48: Andalucía | T48: tienda_fisica
A49: V01982 | B49: 45945 | C49: =YEAR(Tabla2[[#This Row],[fecha]]) -> 2025 | D49: =MONTH(Tabla2[[#This Row],[fecha]]) -> 10 | E49: =TEXT(Tabla2[[#This Row],[fecha]], "mmmm") -> octubre | F49: ="T"&ROUNDUP(Tabla2[[#This Row],[mes]]/3,0) -> T4 | G49: P015 | H49: Zapatillas running | I49: =IF(Tabla2[[#This Row],[precio_unitario]]<=30,"Económico",IF(Tabla2[[#This Row],[precio_unitario]]<=58.49,"Accesible","Caro")) -> Caro | J49: Moda | K49: 2 | L49: 80.75 | M49: 42.31 | N49: 0 | O49: =K49*L49*(1-N49) -> 161.5 | P49: =M49*K49 -> 84.62 | Q49: =O49-P49 -> 76.88 | R49: =IFERROR(Q49/O49,0) -> 0.47603715 | S49: C. Valenciana | T49: online
A50: V00260 | B50: 45809 | C50: =YEAR(Tabla2[[#This Row],[fecha]]) -> 2025 | D50: =MONTH(Tabla2[[#This Row],[fecha]]) -> 6 | E50: =TEXT(Tabla2[[#This Row],[fecha]], "mmmm") -> junio | F50: ="T"&ROUNDUP(Tabla2[[#This Row],[mes]]/3,0) -> T2 | G50: P018 | H50: Crema facial hidratante | I50: =IF(Tabla2[[#This Row],[precio_unitario]]<=30,"Económico",IF(Tabla2[[#This Row],[precio_unitario]]<=58.49,"Accesible","Caro")) -> Accesible | J50: Perfumería y Belleza | K50: 3 | L50: 30.63 | M50: 16.73 | N50: 0 | O50: =K50*L50*(1-N50) -> 91.89 | P50: =M50*K50 -> 50.19 | Q50: =O50-P50 -> 41.7 | R50: =IFERROR(Q50/O50,0) -> 0.45380346 | S50: Madrid | T50: online
A51: V01404 | B51: 45841 | C51: =YEAR(Tabla2[[#This Row],[fecha]]) -> 2025 | D51: =MONTH(Tabla2[[#This Row],[fecha]]) -> 7 | E51: =TEXT(Tabla2[[#This Row],[fecha]], "mmmm") -> julio | F51: ="T"&ROUNDUP(Tabla2[[#This Row],[mes]]/3,0) -> T3 | G51: P005 | H51: Robot de cocina | I51: =IF(Tabla2[[#This Row],[precio_unitario]]<=30,"Económico",IF(Tabla2[[#This Row],[precio_unitario]]<=58.49,"Accesible","Caro")) -> Accesible | J51: Hogar | K51: 4 | L51: 58.47 | M51: 40.71 | N51: 0 | O51: =K51*L51*(1-N51) -> 233.88 | P51: =M51*K51 -> 162.84 | Q51: =O51-P51 -> 71.04 | R51: =IFERROR(Q51/O51,0) -> 0.30374551 | S51: Cataluña | T51: tienda_fisica
...

Sheet TD01_volumen_ventas
A1: año | B1: 2025
A2: comunidad_autonoma | B2: Cataluña
A4: Rótulos de fila | B4: Suma de cantidad
A5: Smartwatch | B5: 80
A6: Chaqueta acolchada | B6: 76
A7: Robot de cocina | B7: 71
A8: Aceite de oliva virgen extra 1L | B8: 70
A9: Crema facial hidratante | B9: 69
A10: Total general | B10: 366

Sheet TD02_ingresos_costes_beneficios
A1: año | B1: 2025
A2: comunidad_autonoma | B2: Cataluña
B4: Valores
A5: Rótulos de fila | B5: Suma de ingresos | C5: Suma de costes | D5: Promedio de beneficio
A6: Tablet 10" | B6: 10466.429 | C6: 5775.8 | D6: 223.36329
A7: Altavoz Bluetooth | B7: 8258.2093 | C7: 5579.13 | D7: 148.83774
A8: Auriculares inalámbricos | B8: 8029.3124 | C8: 5699.8 | D8: 116.47562
A9: Smartwatch | B9: 5535.6745 | C9: 3770.89 | D9: 65.362389
A10: Lámpara LED de pie | B10: 5394.3362 | C10: 3107.35 | D10: 91.479448
A11: Total general | B11: 37683.961 | C11: 23932.97 | D11: 123.88281

Sheet TD03_beneficios_pct
A1: año | B1: 2025
A2: comunidad_autonoma | B2: Cataluña
A4: Rótulos de fila | B4: Promedio de beneficio_pct
A5: Perfume eau de parfum 90ml | B5: 0.52511543
A6: Bolso bandolera | B6: 0.46525942
A7: Tablet 10" | B7: 0.43989436
A8: Café en grano 1kg | B8: 0.43801594
A9: Aceite de oliva virgen extra 1L | B9: 0.43594402
A10: Total general | B10: 0.45588214

Sheet TD04_gama
A1: año | B1: 2025
A2: comunidad_autonoma | B2: Cataluña
A4: Rótulos de fila | B4: Promedio de precio_unitario
A5: Económico
A6: Aceite de oliva virgen extra 1L | B6: 7.8492593
A7: Aspiradora sin cable | B7: 20.15381
A8: Café en grano 1kg | B8: 21.462308
A9: Cava brut nature | B9: 16.393571
A10: Chaqueta acolchada | B10: 14.084643
A11: Chocolate a la taza 500g | B11: 8.782
A12: Crema facial hidratante | B12: 29.713333
A13: Accesible
A14: Champú reparador | B14: 56.924444
A15: Crema facial hidratante | B15: 31.767308
A16: Perfume eau de parfum 90ml | B16: 49.523846
A17: Robot de cocina | B17: 56.762
A18: Set de maquillaje | B18: 57.19
A19: Set de sartenes | B19: 47.638824
A20: Caro
A21: Altavoz Bluetooth | B21: 159.10111
A22: Auriculares inalámbricos | B22: 121.479
A23: Bolso bandolera | B23: 77.850455
A24: Camiseta básica algodón | B24: 75.335833
A25: Champú reparador | B25: 61.852
A26: Lámpara LED de pie | B26: 103.6568
A27: Robot de cocina | B27: 61.779231
A28: Set de maquillaje | B28: 61.972308
A29: Smartwatch | B29: 74.172593
A30: Tablet 10" | B30: 174.10905
A31: Zapatillas running | B31: 78.407895
A32: Total general | B32: 62.165179

Sheet TD05_analisis_productos
A1: año | B1: 2025
A2: comunidad_autonoma | B2: Cataluña
A3: producto | B3: Perfume eau de parfum 90ml
A5: Valores
A6: Suma de cantidad | B6: Suma de ingresos | C6: Promedio de beneficio_pct
A7: 19 | B7: 909.9696 | C7: 0.52511543
A10: año | B10: 2025
A11: comunidad_autonoma | B11: Cataluña
A12: producto | B12: Tablet 10"
A14: Valores
A15: Suma de cantidad | B15: Suma de ingresos | C15: Promedio de beneficio_pct
A16: 61 | B16: 10466.429 | C16: 0.43989436
A18: año | B18: 2025
A19: comunidad_autonoma | B19: Cataluña
A20: producto | B20: Smartwatch
A22: Valores
A23: Suma de cantidad | B23: Suma de ingresos | C23: Promedio de beneficio_pct
A24: 80 | B24: 5535.6745 | C24: 0.32815013

Sheet TD06_beneficios_smartwatch
A1: año | B1: 2025
A2: comunidad_autonoma | B2: Cataluña
A4: Rótulos de fila | B4: Promedio de beneficio_pct
A5: Alimentación | B5: 0.37248657
A6: Café en grano 1kg | B6: 0.43801594
A7: Aceite de oliva virgen extra 1L | B7: 0.43594402
A8: Chocolate a la taza 500g | B8: 0.31482135
A9: Cava brut nature | B9: 0.29222926
A10: Electrónica | B10: 0.3405551
A11: Tablet 10" | B11: 0.43989436
A12: Smartwatch | B12: 0.32815013
A13: Altavoz Bluetooth | B13: 0.3078361
A14: Auriculares inalámbricos | B14: 0.28244268
A15: Hogar | B15: 0.3684397
A16: Lámpara LED de pie | B16: 0.41967311
... A30: Total general | B30: 0.3778581

Sheet KPIS
B2: KPIS DE NEGOCIO | C2: CATALUÑA Y 2025
B4: Unidades Totales Vendidas | C4: =GETPIVOTDATA("cantidad",TD01_volumen_ventas!$A$4) -> 366
B6: Ingresos Totales | C6: =GETPIVOTDATA("Suma de ingresos",TD02_ingresos_costes_beneficios!$A$4) -> 37683.961
B8: Costes Totales | C8: =GETPIVOTDATA("Suma de costes",TD02_ingresos_costes_beneficios!$A$4) -> 23932.97
B10: Beneficio Promedio | C10: =GETPIVOTDATA("Promedio de beneficio",TD02_ingresos_costes_beneficios!$A$4) -> 123.88281
B12: Margen de Beneficio Promedio | C12: =GETPIVOTDATA("beneficio_pct",TD03_beneficios_pct!$A$4) -> 0.45588214

Sheet TOP_productos
B2: TOP 1 PRODUCTOS DE NEGOCIO | C2: CATALUÑA Y 2025
B4: Productos Volumen | C4: =TD01_volumen_ventas!A5 -> Smartwatch
B5: Producto ingresos | C5: =TD02_ingresos_costes_beneficios!$A$6 -> Tablet 10"
B6: Producto Costes | C6: =TD02_ingresos_costes_beneficios!$A$6 -> Tablet 10"
B7: Producto Beneficio promedio | C7: =TD03_beneficios_pct!A5 -> Perfume eau de parfum 90ml

Sheet informe_final
F1: INFORME DE PRODUCTOS DE NEGOCIO: CATALUÑA Y 2025
C3: Producto de Volumen | D3: Estrategia | F3: Producto de Ingresos | G3: Estrategia | I3: Producto de beneficios | J3: Estrategia
C4: Smartwatch | D4: Mantener el producto como referencia de volumen, evitando incrementos de precio | F4: Tablet 10 | G4: Potenciar su promoción entre clientes con mayor poder adquisitivo. | I4: Perfume eau de parfum 90ml | J4: Oportunidad de aumentar su visibilidad mediante acciones de publicidad y promoción.
C6: Producto | D6: Suma de cantidad | F6: Rótulos de fila | G6: Suma de ingresos | I6: Rótulos de fila | J6: Promedio de beneficio_pct
C7: Smartwatch | D7: 80 | F7: Tablet 10" | G7: 10466.429 | I7: Perfume eau de parfum 90ml | J7: 0.52511543
C8: Chaqueta acolchada | D8: 76 | F8: Altavoz Bluetooth | G8: 8258.2093 | I8: Bolso bandolera | J8: 0.46525942
C9: Robot de cocina | D9: 71 | F9: Auriculares inalámbricos | G9: 8029.3124 | I9: Tablet 10" | J9: 0.43989436
C10: Aceite de oliva virgen extra 1L | D10: 70 | F10: Smartwatch | G10: 5535.6745 | I10: Café en grano 1kg | J10: 0.43801594
C11: Crema facial hidratante | D11: 69 | F11: Lámpara LED de pie | G11: 5394.3362 | I11: Aceite de oliva virgen extra 1L | J11: 0.43594402
C12: Total general | D12: 366 | F12: Total general | G12: 37683.961 | I12: Total general | J12: 0.45588214
